Workbook
Name Расходы_список: Настройки!$J$6:INDEX(Настройки!$J:$J,MAX(6,SUMPRODUCT(MAX((Настройки!$J$6:$J$35<>"")*ROW(Настройки!$J$6:$J$35)))))
Name Доходы_список: Настройки!$L$6:INDEX(Настройки!$L:$L,MAX(6,SUMPRODUCT(MAX((Настройки!$L$6:$L$17<>"")*ROW(Настройки!$L$6:$L$17)))))
Name Счета_список: Настройки!$N$6:INDEX(Настройки!$N:$N,MAX(6,SUMPRODUCT(MAX((Настройки!$N$6:$N$17<>"")*ROW(Настройки!$N$6:$N$17)))))
Name Даты_месяца: Операции!$S$10:INDEX(Операции!$S:$S,9+Операции!$S$9)

Sheet Инструкция
B2: Трекер и планер расходов
B3: План и факт в одном файле · помесячная статистика за учётный год · всё считается формулами
B5: Куда что вносить
B6: Операции | C6: Каждый день: что потратила, что пришло, откуда и куда. Тип «Перевод» — снятие наличных, погашение кредитки, перевод между картами: он меняет только остатки счетов.
B7: Журнал | C7: Запланированные разовые траты: дата, категория, что, сумма, статус «Запланировано». Заплатила — «Оплачено», счёт (и сумма факт, если отличалась). В «Операции» её не вносишь.
B8: Постоянные | C8: Аренда, связь, подписки, зарплата — один раз строкой. Каждый месяц: ✓ — оплачено по плану, число — оплачено столько, пусто — ещё нет. «Действует с / по» — для подписок, которые начинаются или заканчиваются.
B9: Покупки | C9: Крупные покупки с датой. Купила — ✓ в «Куплено», цена факт и счёт.
B10: Долги | C10: Кредиты и рассрочки с прогрессом погашения.
B11: Правило | C11: Каждая трата живёт в одном месте. Если в «Операциях» или «Журнале» появится то, что уже есть в другом месте, колонка «Возможный дубль» подсветится жёлтым.
B13: Что смотреть
B14: Счета | C14: Сколько сейчас на каждой карте, в наличных и сколько долга по кредитке. Остатки на начало вводишь один раз; внизу — проверка, нет ли оплат без счёта.
B15: Месяц | C15: Выбери любой месяц учётного года: по категориям лимит, план, факт, остаток лимита; куда ушли деньги и траты по дням.
B16: Прогноз | C16: Три месяца вперёд по неделям: хватит ли денег и где остаток опускается ниже подушки.
B17: Статистика | C17: 12 месяцев подряд: доход и расход план/факт, баланс, накоплено, самый дорогой месяц; таблица «категория × месяц» с подсветкой и главные статьи за год.
B19: Настройки
B20: Прогноз с | C20: Месяц начала прогноза — сдвигай как хочешь.
B21: Учёт с | C21: Начало учётного года (сейчас октябрь 2026). Отметки ✓ на «Постоянных» привязаны к нему — меняй только в новом файле через год.
B22: Списки | C22: Категории, счета, статусы. Новая строка в конце списка сразу появляется в меню.
B23: Деньги на старте | C23: Больше не вводятся: считаются по остаткам счетов.
B25: Цвета
B26: Жёлтая заливка, синий текст | C26: Ячейки для ввода. Всё остальное — формулы.
B27: Зелёная строка журнала | C27: Оплачено. Красная — просрочено. Жёлтая — срок в ближайшие 7 дней.
B28: Оранжевая клетка месяца | C28: В «Постоянных» вписана сумма, отличная от плана.
B29: Серая клетка месяца | C29: Платёж в этом месяце не действует (вне «с / по»).

Sheet Настройки
B2: Настройки
B3: Период прогноза, учётный год и деньги на старте
J4: Списки для меню — правь под себя; новая строка сразу появляется в меню
B5: Период и деньги | J5: Категории расходов | L5: Категории доходов | N5: Счета | P5: Статус | R5: Приоритет | T5: Тип | V5: Месяцы | X5: Месяцы учёта
B6: Прогноз: год начала | C6: 2026 | E6: Горизонт прогноза | F6: =DATE($C$6,$D$7,1) | G6: =DATE($C$6,$D$7+3,1)-1 | J6: Жильё | L6: Зарплата | N6: Карта | P6: Запланировано | R6: Обязательно | T6: Расход | V6: Январь | X6: =INDEX($V$6:$V$17,MONTH(DATE($C$8,$D$9+0,1)))&" "&YEAR(DATE($C$8,$D$9+0,1))
B7: Прогноз: месяц начала | C7: Октябрь | D7: =IFERROR(MATCH($C$7,$V$6:$V$17,0),1) | J7: Продукты | L7: Премия | N7: Наличные | P7: Оплачено | R7: Желательно | T7: Доход | V7: Февраль | X7: =INDEX($V$6:$V$17,MONTH(DATE($C$8,$D$9+1,1)))&" "&YEAR(DATE($C$8,$D$9+1,1))
B8: Учёт: год начала | C8: 2026 | E8: Учётный год | F8: =DATE($C$8,$D$9,1) | G8: =DATE($C$8,$D$9+12,1)-1 | J8: Транспорт | N8: Кредитка | P8: Перенесено | R8: Можно отложить | V8: Март | X8: =INDEX($V$6:$V$17,MONTH(DATE($C$8,$D$9+2,1)))&" "&YEAR(DATE($C$8,$D$9+2,1))
B9: Учёт: месяц начала | C9: Октябрь | D9: =IFERROR(MATCH($C$9,$V$6:$V$17,0),1) | J9: Подписки | P9: Отменено | V9: Апрель | X9: =INDEX($V$6:$V$17,MONTH(DATE($C$8,$D$9+3,1)))&" "&YEAR(DATE($C$8,$D$9+3,1))
B10: Деньги на старте прогноза (по счетам) | C10: =SUM(Счета!$D$10:$D$21)+SUMIFS(Операции!$Q$10:$Q$1009,Операции!$D$10:$D$1009,"Доход",Операции!$C$10:$C$1009,">="&Счета!$C$4,Операции!$C$10:$C$1009,"<"&DATE(Настройки!$C$6,Настройки!$D$7,1))-SUMIFS(Операции!$Q$10:$Q$1009,Операции!$D$10:$D$1009,"Расход",Операции!$C$10:$C$1009,">="&Счета!$C$4,Операции!$C$10:$C$1009,"<"&DATE(Настройки!$C$6,Настройки!$D$7,1))+SUMIFS(Журнал!$P$10:$P$1509,Журнал!$D$10:$D$1509,"Доход",Журнал!$R$10:$R$1509,">="&DATE(YEAR(Счета!$C$4),MONTH(Счета!$C$4),1),Журнал!$R$10:$R$1509,"<"&DATE(Настройки!$C$6,Настройки!$D$7,1))-SUMIFS(Журнал!$P$10:$P$1509,Журнал!$D$10:$D$1509,"<>Доход",Журнал!$R$10:$R$1509,">="&DATE(YEAR(Счета!$C$4),MONTH(Счета!$C$4),1),Журнал!$R$10:$R$1509,"<"&DATE(Настройки!$C$6,Настройки!$D$7,1))+SUMIFS(Постоянные!$AC$8:$AC$367,Постоянные!$Z$8:$Z$367,"Доход",Постоянные!$Y$8:$Y$367,">="&Счета!$C$4,Постоянные!$Y$8:$Y$367,"<"&DATE(Настройки!$C$6,Настройки!$D$7,1))-SUMIFS(Постоянные!$AC$8:$AC$367,Постоянные!$Z$8:$Z$367,"Расход",Постоянные!$Y$8:$Y$367,">="&Счета!$C$4,Постоянные!$Y$8:$Y$367,"<"&DATE(Настройки!$C$6,Настройки!$D$7,1))-SUMIFS(Покупки!$S$7:$S$18,Покупки!$G$7:$G$18,">="&Счета!$C$4,Покупки!$G$7:$G$18,"<"&DATE(Настройки!$C$6,Настройки!$D$7,1)) | J10: Техника | V10: Май | X10: =INDEX($V$6:$V$17,MONTH(DATE($C$8,$D$9+4,1)))&" "&YEAR(DATE($C$8,$D$9+4,1))
B11: Неприкосновенный запас (подушка) | C11: 100 | V11: Июнь | X11: =INDEX($V$6:$V$17,MONTH(DATE($C$8,$D$9+5,1)))&" "&YEAR(DATE($C$8,$D$9+5,1))
V12: Июль | X12: =INDEX($V$6:$V$17,MONTH(DATE($C$8,$D$9+6,1)))&" "&YEAR(DATE($C$8,$D$9+6,1))
B13: Прогноз — три месяца вперёд, сдвигай его как угодно. Учётный год — 12 месяцев статистики; отметки ✓ на «Постоянных» привязаны к нему, поэтому его начало меняют только при переходе на новый файл. | V13: Август | X13: =INDEX($V$6:$V$17,MONTH(DATE($C$8,$D$9+7,1)))&" "&YEAR(DATE($C$8,$D$9+7,1))
V14: Сентябрь | X14: =INDEX($V$6:$V$17,MONTH(DATE($C$8,$D$9+8,1)))&" "&YEAR(DATE($C$8,$D$9+8,1))
V15: Октябрь | X15: =INDEX($V$6:$V$17,MONTH(DATE($C$8,$D$9+9,1)))&" "&YEAR(DATE($C$8,$D$9+9,1))
V16: Ноябрь | X16: =INDEX($V$6:$V$17,MONTH(DATE($C$8,$D$9+10,1)))&" "&YEAR(DATE($C$8,$D$9+10,1))
V17: Декабрь | X17: =INDEX($V$6:$V$17,MONTH(DATE($C$8,$D$9+11,1)))&" "&YEAR(DATE($C$8,$D$9+11,1))

Sheet Операции
B2: Операции
B3: Каждый день: трата, поступление или перевод между счетами (снятие наличных, погашение кредитки)
B5: Сводка: | C5: Потрачено сегодня | E5: Потрачено за выбранный месяц | F5: Поступило за выбранный месяц | G5: Строк без счёта | I5: Возможных дублей
C6: =SUMIFS($Q$10:$Q$1009,$D$10:$D$1009,"Расход",$C$10:$C$1009,TODAY()) | E6: =SUMIFS($Q$10:$Q$1009,$D$10:$D$1009,"Расход",$P$10:$P$1009,$S$8) | F6: =SUMIFS($Q$10:$Q$1009,$D$10:$D$1009,"Доход",$P$10:$P$1009,$S$8) | G6: =COUNTIFS($G$10:$G$1009,"<>",$H$10:$H$1009,"") | I6: =COUNTIF($K$10:$K$1009,"?*")
C7: Месяц | D7: Октябрь 2026 | F7: ← выбери месяц: в колонке «Дата» появятся его дни (другую дату можно вписать вручную)
S8: =IFERROR(DATE(Настройки!$C$8,Настройки!$D$9+MATCH($D$7,Настройки!$X$6:$X$17,0)-1,1),DATE(YEAR(TODAY()),MONTH(TODAY()),1))
B9: № | C9: Дата | D9: Тип | E9: Категория | F9: Что | G9: Сумма | H9: Счёт | I9: На счёт (для перевода) | J9: Месяц | K9: Возможный дубль | S9: =DAY(DATE(YEAR($S$8),MONTH($S$8)+1,1)-1)
B10: =IF(AND($C10="",$F10=""),"",ROW()-9) | C10: 46307 | D10: Расход | E10: Продукты | F10: Магазин | G10: -30 | H10: Кредитка | J10: =IF($C10="","",INDEX(Настройки!$V$6:$V$17,MONTH($C10))&" "&YEAR($C10)) | K10: =IF(OR($F10="",$D10="Перевод"),"",IF(AND(N($G10)<>0,COUNTIFS(Журнал!$C$10:$C$1509,$C10,Журнал!$P$10:$P$1509,$G10)>0),"есть в Журнале",IF(COUNTIF(Постоянные!$C$8:$C$37,$F10)>0,"есть в Постоянных",IF(COUNTIF(Покупки!$C$7:$C$18,$F10)>0,"есть в Покупках","")))) | P10: =IF($C10="","",DATE(YEAR($C10),MONTH($C10),1)) | Q10: =IF(ISNUMBER($G10),ABS($G10),0) | R10: =IF(AND($D10="Расход",COUNTIFS(Счета!$B$10:$B$21,$H10,Счета!$C$10:$C$21,"Кредитная")>0),1,0) | S10: =IF(1<=$S$9,DATE(YEAR($S$8),MONTH($S$8),1),"")
B11: =IF(AND($C11="",$F11=""),"",ROW()-9) | C11: 46308 | D11: Перевод | F11: Снятие | G11: 100 | H11: Карта | I11: Наличные | J11: =IF($C11="","",INDEX(Настройки!$V$6:$V$17,MONTH($C11))&" "&YEAR($C11)) | K11: =IF(OR($F11="",$D11="Перевод"),"",IF(AND(N($G11)<>0,COUNTIFS(Журнал!$C$10:$C$1509,$C11,Журнал!$P$10:$P$1509,$G11)>0),"есть в Журнале",IF(COUNTIF(Постоянные!$C$8:$C$37,$F11)>0,"есть в Постоянных",IF(COUNTIF(Покупки!$C$7:$C$18,$F11)>0,"есть в Покупках","")))) | P11: =IF($C11="","",DATE(YEAR($C11),MONTH($C11),1)) | Q11: =IF(ISNUMBER($G11),ABS($G11),0) | R11: =IF(AND($D11="Расход",COUNTIFS(Счета!$B$10:$B$21,$H11,Счета!$C$10:$C$21,"Кредитная")>0),1,0) | S11: =IF(2<=$S$9,DATE(YEAR($S$8),MONTH($S$8),2),"")
B12: =IF(AND($C12="",$F12=""),"",ROW()-9) | C12: 46309 | D12: Расход | E12: Транспорт | F12: Билет | G12: 20 | H12: Наличные | J12: =IF($C12="","",INDEX(Настройки!$V$6:$V$17,MONTH($C12))&" "&YEAR($C12)) | K12: =IF(OR($F12="",$D12="Перевод"),"",IF(AND(N($G12)<>0,COUNTIFS(Журнал!$C$10:$C$1509,$C12,Журнал!$P$10:$P$1509,$G12)>0),"есть в Журнале",IF(COUNTIF(Постоянные!$C$8:$C$37,$F12)>0,"есть в Постоянных",IF(COUNTIF(Покупки!$C$7:$C$18,$F12)>0,"есть в Покупках","")))) | P12: =IF($C12="","",DATE(YEAR($C12),MONTH($C12),1)) | Q12: =IF(ISNUMBER($G12),ABS($G12),0) | R12: =IF(AND($D12="Расход",COUNTIFS(Счета!$B$10:$B$21,$H12,Счета!$C$10:$C$21,"Кредитная")>0),1,0) | S12: =IF(3<=$S$9,DATE(YEAR($S$8),MONTH($S$8),3),"")
B13: =IF(AND($C13="",$F13=""),"",ROW()-9) | C13: 46315 | D13: Перевод | F13: Погашение кредитки | G13: 30 | H13: Карта | I13: Кредитка | J13: =IF($C13="","",INDEX(Настройки!$V$6:$V$17,MONTH($C13))&" "&YEAR($C13)) | K13: =IF(OR($F13="",$D13="Перевод"),"",IF(AND(N($G13)<>0,COUNTIFS(Журнал!$C$10:$C$1509,$C13,Журнал!$P$10:$P$1509,$G13)>0),"есть в Журнале",IF(COUNTIF(Постоянные!$C$8:$C$37,$F13)>0,"есть в Постоянных",IF(COUNTIF(Покупки!$C$7:$C$18,$F13)>0,"есть в Покупках","")))) | P13: =IF($C13="","",DATE(YEAR($C13),MONTH($C13),1)) | Q13: =IF(ISNUMBER($G13),ABS($G13),0) | R13: =IF(AND($D13="Расход",COUNTIFS(Счета!$B$10:$B$21,$H13,Счета!$C$10:$C$21,"Кредитная")>0),1,0) | S13: =IF(4<=$S$9,DATE(YEAR($S$8),MONTH($S$8),4),"")
B14: =IF(AND($C14="",$F14=""),"",ROW()-9) | C14: 46316 | D14: Доход | E14: Премия | F14: Кэшбэк | G14: 5 | H14: Карта | J14: =IF($C14="","",INDEX(Настройки!$V$6:$V$17,MONTH($C14))&" "&YEAR($C14)) | K14: =IF(OR($F14="",$D14="Перевод"),"",IF(AND(N($G14)<>0,COUNTIFS(Журнал!$C$10:$C$1509,$C14,Журнал!$P$10:$P$1509,$G14)>0),"есть в Журнале",IF(COUNTIF(Постоянные!$C$8:$C$37,$F14)>0,"есть в Постоянных",IF(COUNTIF(Покупки!$C$7:$C$18,$F14)>0,"есть в Покупках","")))) | P14: =IF($C14="","",DATE(YEAR($C14),MONTH($C14),1)) | Q14: =IF(ISNUMBER($G14),ABS($G14),0) | R14: =IF(AND($D14="Расход",COUNTIFS(Счета!$B$10:$B$21,$H14,Счета!$C$10:$C$21,"Кредитная")>0),1,0) | S14: =IF(5<=$S$9,DATE(YEAR($S$8),MONTH($S$8),5),"")
B15: =IF(AND($C15="",$F15=""),"",ROW()-9) | C15: 46301 | D15: Расход | E15: Продукты | F15: Кафе | G15: 100 | H15: Карта | J15: =IF($C15="","",INDEX(Настройки!$V$6:$V$17,MONTH($C15))&" "&YEAR($C15)) | K15: =IF(OR($F15="",$D15="Перевод"),"",IF(AND(N($G15)<>0,COUNTIFS(Журнал!$C$10:$C$1509,$C15,Журнал!$P$10:$P$1509,$G15)>0),"есть в Журнале",IF(COUNTIF(Постоянные!$C$8:$C$37,$F15)>0,"есть в Постоянных",IF(COUNTIF(Покупки!$C$7:$C$18,$F15)>0,"есть в Покупках","")))) | P15: =IF($C15="","",DATE(YEAR($C15),MONTH($C15),1)) | Q15: =IF(ISNUMBER($G15),ABS($G15),0) | R15: =IF(AND($D15="Расход",COUNTIFS(Счета!$B$10:$B$21,$H15,Счета!$C$10:$C$21,"Кредитная")>0),1,0) | S15: =IF(6<=$S$9,DATE(YEAR($S$8),MONTH($S$8),6),"")
B16: =IF(AND($C16="",$F16=""),"",ROW()-9) | J16: =IF($C16="","",INDEX(Настройки!$V$6:$V$17,MONTH($C16))&" "&YEAR($C16)) | K16: =IF(OR($F16="",$D16="Перевод"),"",IF(AND(N($G16)<>0,COUNTIFS(Журнал!$C$10:$C$1509,$C16,Журнал!$P$10:$P$1509,$G16)>0),"есть в Журнале",IF(COUNTIF(Постоянные!$C$8:$C$37,$F16)>0,"есть в Постоянных",IF(COUNTIF(Покупки!$C$7:$C$18,$F16)>0,"есть в Покупках","")))) | P16: =IF($C16="","",DATE(YEAR($C16),MONTH($C16),1)) | Q16: =IF(ISNUMBER($G16),ABS($G16),0) | R16: =IF(AND($D16="Расход",COUNTIFS(Счета!$B$10:$B$21,$H16,Счета!$C$10:$C$21,"Кредитная")>0),1,0) | S16: =IF(7<=$S$9,DATE(YEAR($S$8),MONTH($S$8),7),"")
B17: =IF(AND($C17="",$F17=""),"",ROW()-9) | J17: =IF($C17="","",INDEX(Настройки!$V$6:$V$17,MONTH($C17))&" "&YEAR($C17)) | K17: =IF(OR($F17="",$D17="Перевод"),"",IF(AND(N($G17)<>0,COUNTIFS(Журнал!$C$10:$C$1509,$C17,Журнал!$P$10:$P$1509,$G17)>0),"есть в Журнале",IF(COUNTIF(Постоянные!$C$8:$C$37,$F17)>0,"есть в Постоянных",IF(COUNTIF(Покупки!$C$7:$C$18,$F17)>0,"есть в Покупках","")))) | P17: =IF($C17="","",DATE(YEAR($C17),MONTH($C17),1)) | Q17: =IF(ISNUMBER($G17),ABS($G17),0) | R17: =IF(AND($D17="Расход",COUNTIFS(Счета!$B$10:$B$21,$H17,Счета!$C$10:$C$21,"Кредитная")>0),1,0) | S17: =IF(8<=$S$9,DATE(YEAR($S$8),MONTH($S$8),8),"")
B18: =IF(AND($C18="",$F18=""),"",ROW()-9) | J18: =IF($C18="","",INDEX(Настройки!$V$6:$V$17,MONTH($C18))&" "&YEAR($C18)) | K18: =IF(OR($F18="",$D18="Перевод"),"",IF(AND(N($G18)<>0,COUNTIFS(Журнал!$C$10:$C$1509,$C18,Журнал!$P$10:$P$1509,$G18)>0),"есть в Журнале",IF(COUNTIF(Постоянные!$C$8:$C$37,$F18)>0,"есть в Постоянных",IF(COUNTIF(Покупки!$C$7:$C$18,$F18)>0,"есть в Покупках","")))) | P18: =IF($C18="","",DATE(YEAR($C18),MONTH($C18),1)) | Q18: =IF(ISNUMBER($G18),ABS($G18),0) | R18: =IF(AND($D18="Расход",COUNTIFS(Счета!$B$10:$B$21,$H18,Счета!$C$10:$C$21,"Кредитная")>0),1,0) | S18: =IF(9<=$S$9,DATE(YEAR($S$8),MONTH($S$8),9),"")
B19: =IF(AND($C19="",$F19=""),"",ROW()-9) | J19: =IF($C19="","",INDEX(Настройки!$V$6:$V$17,MONTH($C19))&" "&YEAR($C19)) | K19: =IF(OR($F19="",$D19="Перевод"),"",IF(AND(N($G19)<>0,COUNTIFS(Журнал!$C$10:$C$1509,$C19,Журнал!$P$10:$P$1509,$G19)>0),"есть в Журнале",IF(COUNTIF(Постоянные!$C$8:$C$37,$F19)>0,"есть в Постоянных",IF(COUNTIF(Покупки!$C$7:$C$18,$F19)>0,"есть в Покупках","")))) | P19: =IF($C19="","",DATE(YEAR($C19),MONTH($C19),1)) | Q19: =IF(ISNUMBER($G19),ABS($G19),0) | R19: =IF(AND($D19="Расход",COUNTIFS(Счета!$B$10:$B$21,$H19,Счета!$C$10:$C$21,"Кредитная")>0),1,0) | S19: =IF(10<=$S$9,DATE(YEAR($S$8),MONTH($S$8),10),"")
B20: =IF(AND($C20="",$F20=""),"",ROW()-9) | J20: =IF($C20="","",INDEX(Настройки!$V$6:$V$17,MONTH($C20))&" "&YEAR($C20)) | K20: =IF(OR($F20="",$D20="Перевод"),"",IF(AND(N($G20)<>0,COUNTIFS(Журнал!$C$10:$C$1509,$C20,Журнал!$P$10:$P$1509,$G20)>0),"есть в Журнале",IF(COUNTIF(Постоянные!$C$8:$C$37,$F20)>0,"есть в Постоянных",IF(COUNTIF(Покупки!$C$7:$C$18,$F20)>0,"есть в Покупках","")))) | P20: =IF($C20="","",DATE(YEAR($C20),MONTH($C20),1)) | Q20: =IF(ISNUMBER($G20),ABS($G20),0) | R20: =IF(AND($D20="Расход",COUNTIFS(Счета!$B$10:$B$21,$H20,Счета!$C$10:$C$21,"Кредитная")>0),1,0) | S20: =IF(11<=$S$9,DATE(YEAR($S$8),MONTH($S$8),11),"")
B21: =IF(AND($C21="",$F21=""),"",ROW()-9) | J21: =IF($C21="","",INDEX(Настройки!$V$6:$V$17,MONTH($C21))&" "&YEAR($C21)) | K21: =IF(OR($F21="",$D21="Перевод"),"",IF(AND(N($G21)<>0,COUNTIFS(Журнал!$C$10:$C$1509,$C21,Журнал!$P$10:$P$1509,$G21)>0),"есть в Журнале",IF(COUNTIF(Постоянные!$C$8:$C$37,$F21)>0,"есть в Постоянных",IF(COUNTIF(Покупки!$C$7:$C$18,$F21)>0,"есть в Покупках","")))) | P21: =IF($C21="","",DATE(YEAR($C21),MONTH($C21),1)) | Q21: =IF(ISNUMBER($G21),ABS($G21),0) | R21: =IF(AND($D21="Расход",COUNTIFS(Счета!$B$10:$B$21,$H21,Счета!$C$10:$C$21,"Кредитная")>0),1,0) | S21: =IF(12<=$S$9,DATE(YEAR($S$8),MONTH($S$8),12),"")
B22: =IF(AND($C22="",$F22=""),"",ROW()-9) | J22: =IF($C22="","",INDEX(Настройки!$V$6:$V$17,MONTH($C22))&" "&YEAR($C22)) | K22: =IF(OR($F22="",$D22="Перевод"),"",IF(AND(N($G22)<>0,COUNTIFS(Журнал!$C$10:$C$1509,$C22,Журнал!$P$10:$P$1509,$G22)>0),"есть в Журнале",IF(COUNTIF(Постоянные!$C$8:$C$37,$F22)>0,"есть в Постоянных",IF(COUNTIF(Покупки!$C$7:$C$18,$F22)>0,"есть в Покупках","")))) | P22: =IF($C22="","",DATE(YEAR($C22),MONTH($C22),1)) | Q22: =IF(ISNUMBER($G22),ABS($G22),0) | R22: =IF(AND($D22="Расход",COUNTIFS(Счета!$B$10:$B$21,$H22,Счета!$C$10:$C$21,"Кредитная")>0),1,0) | S22: =IF(13<=$S$9,DATE(YEAR($S$8),MONTH($S$8),13),"")
B23: =IF(AND($C23="",$F23=""),"",ROW()-9) | J23: =IF($C23="","",INDEX(Настройки!$V$6:$V$17,MONTH($C23))&" "&YEAR($C23)) | K23: =IF(OR($F23="",$D23="Перевод"),"",IF(AND(N($G23)<>0,COUNTIFS(Журнал!$C$10:$C$1509,$C23,Журнал!$P$10:$P$1509,$G23)>0),"есть в Журнале",IF(COUNTIF(Постоянные!$C$8:$C$37,$F23)>0,"есть в Постоянных",IF(COUNTIF(Покупки!$C$7:$C$18,$F23)>0,"есть в Покупках","")))) | P23: =IF($C23="","",DATE(YEAR($C23),MONTH($C23),1)) | Q23: =IF(ISNUMBER($G23),ABS($G23),0) | R23: =IF(AND($D23="Расход",COUNTIFS(Счета!$B$10:$B$21,$H23,Счета!$C$10:$C$21,"Кредитная")>0),1,0) | S23: =IF(14<=$S$9,DATE(YEAR($S$8),MONTH($S$8),14),"")
B24: =IF(AND($C24="",$F24=""),"",ROW()-9) | J24: =IF($C24="","",INDEX(Настройки!$V$6:$V$17,MONTH($C24))&" "&YEAR($C24)) | K24: =IF(OR($F24="",$D24="Перевод"),"",IF(AND(N($G24)<>0,COUNTIFS(Журнал!$C$10:$C$1509,$C24,Журнал!$P$10:$P$1509,$G24)>0),"есть в Журнале",IF(COUNTIF(Постоянные!$C$8:$C$37,$F24)>0,"есть в Постоянных",IF(COUNTIF(Покупки!$C$7:$C$18,$F24)>0,"есть в Покупках","")))) | P24: =IF($C24="","",DATE(YEAR($C24),MONTH($C24),1)) | Q24: =IF(ISNUMBER($G24),ABS($G24),0) | R24: =IF(AND($D24="Расход",COUNTIFS(Счета!$B$10:$B$21,$H24,Счета!$C$10:$C$21,"Кредитная")>0),1,0) | S24: =IF(15<=$S$9,DATE(YEAR($S$8),MONTH($S$8),15),"")
B25: =IF(AND($C25="",$F25=""),"",ROW()-9) | J25: =IF($C25="","",INDEX(Настройки!$V$6:$V$17,MONTH($C25))&" "&YEAR($C25)) | K25: =IF(OR($F25="",$D25="Перевод"),"",IF(AND(N($G25)<>0,COUNTIFS(Журнал!$C$10:$C$1509,$C25,Журнал!$P$10:$P$1509,$G25)>0),"есть в Журнале",IF(COUNTIF(Постоянные!$C$8:$C$37,$F25)>0,"есть в Постоянных",IF(COUNTIF(Покупки!$C$7:$C$18,$F25)>0,"есть в Покупках","")))) | P25: =IF($C25="","",DATE(YEAR($C25),MONTH($C25),1)) | Q25: =IF(ISNUMBER($G25),ABS($G25),0) | R25: =IF(AND($D25="Расход",COUNTIFS(Счета!$B$10:$B$21,$H25,Счета!$C$10:$C$21,"Кредитная")>0),1,0) | S25: =IF(16<=$S$9,DATE(YEAR($S$8),MONTH($S$8),16),"")
B26: =IF(AND($C26="",$F26=""),"",ROW()-9) | J26: =IF($C26="","",INDEX(Настройки!$V$6:$V$17,MONTH($C26))&" "&YEAR($C26)) | K26: =IF(OR($F26="",$D26="Перевод"),"",IF(AND(N($G26)<>0,COUNTIFS(Журнал!$C$10:$C$1509,$C26,Журнал!$P$10:$P$1509,$G26)>0),"есть в Журнале",IF(COUNTIF(Постоянные!$C$8:$C$37,$F26)>0,"есть в Постоянных",IF(COUNTIF(Покупки!$C$7:$C$18,$F26)>0,"есть в Покупках","")))) | P26: =IF($C26="","",DATE(YEAR($C26),MONTH($C26),1)) | Q26: =IF(ISNUMBER($G26),ABS($G26),0) | R26: =IF(AND($D26="Расход",COUNTIFS(Счета!$B$10:$B$21,$H26,Счета!$C$10:$C$21,"Кредитная")>0),1,0) | S26: =IF(17<=$S$9,DATE(YEAR($S$8),MONTH($S$8),17),"")
B27: =IF(AND($C27="",$F27=""),"",ROW()-9) | J27: =IF($C27="","",INDEX(Настройки!$V$6:$V$17,MONTH($C27))&" "&YEAR($C27)) | K27: =IF(OR($F27="",$D27="Перевод"),"",IF(AND(N($G27)<>0,COUNTIFS(Журнал!$C$10:$C$1509,$C27,Журнал!$P$10:$P$1509,$G27)>0),"есть в Журнале",IF(COUNTIF(Постоянные!$C$8:$C$37,$F27)>0,"есть в Постоянных",IF(COUNTIF(Покупки!$C$7:$C$18,$F27)>0,"есть в Покупках","")))) | P27: =IF($C27="","",DATE(YEAR($C27),MONTH($C27),1)) | Q27: =IF(ISNUMBER($G27),ABS($G27),0) | R27: =IF(AND($D27="Расход",COUNTIFS(Счета!$B$10:$B$21,$H27,Счета!$C$10:$C$21,"Кредитная")>0),1,0) | S27: =IF(18<=$S$9,DATE(YEAR($S$8),MONTH($S$8),18),"")
B28: =IF(AND($C28="",$F28=""),"",ROW()-9) | J28: =IF($C28="","",INDEX(Настройки!$V$6:$V$17,MONTH($C28))&" "&YEAR($C28)) | K28: =IF(OR($F28="",$D28="Перевод"),"",IF(AND(N($G28)<>0,COUNTIFS(Журнал!$C$10:$C$1509,$C28,Журнал!$P$10:$P$1509,$G28)>0),"есть в Журнале",IF(COUNTIF(Постоянные!$C$8:$C$37,$F28)>0,"есть в Постоянных",IF(COUNTIF(Покупки!$C$7:$C$18,$F28)>0,"есть в Покупках","")))) | P28: =IF($C28="","",DATE(YEAR($C28),MONTH($C28),1)) | Q28: =IF(ISNUMBER($G28),ABS($G28),0) | R28: =IF(AND($D28="Расход",COUNTIFS(Счета!$B$10:$B$21,$H28,Счета!$C$10:$C$21,"Кредитная")>0),1,0) | S28: =IF(19<=$S$9,DATE(YEAR($S$8),MONTH($S$8),19),"")
B29: =IF(AND($C29="",$F29=""),"",ROW()-9) | J29: =IF($C29="","",INDEX(Настройки!$V$6:$V$17,MONTH($C29))&" "&YEAR($C29)) | K29: =IF(OR($F29="",$D29="Перевод"),"",IF(AND(N($G29)<>0,COUNTIFS(Журнал!$C$10:$C$1509,$C29,Журнал!$P$10:$P$1509,$G29)>0),"есть в Журнале",IF(COUNTIF(Постоянные!$C$8:$C$37,$F29)>0,"есть в Постоянных",IF(COUNTIF(Покупки!$C$7:$C$18,$F29)>0,"есть в Покупках","")))) | P29: =IF($C29="","",DATE(YEAR($C29),MONTH($C29),1)) | Q29: =IF(ISNUMBER($G29),ABS($G29),0) | R29: =IF(AND($D29="Расход",COUNTIFS(Счета!$B$10:$B$21,$H29,Счета!$C$10:$C$21,"Кредитная")>0),1,0) | S29: =IF(20<=$S$9,DATE(YEAR($S$8),MONTH($S$8),20),"")
B30: =IF(AND($C30="",$F30=""),"",ROW()-9) | J30: =IF($C30="","",INDEX(Настройки!$V$6:$V$17,MONTH($C30))&" "&YEAR($C30)) | K30: =IF(OR($F30="",$D30="Перевод"),"",IF(AND(N($G30)<>0,COUNTIFS(Журнал!$C$10:$C$1509,$C30,Журнал!$P$10:$P$1509,$G30)>0),"есть в Журнале",IF(COUNTIF(Постоянные!$C$8:$C$37,$F30)>0,"есть в Постоянных",IF(COUNTIF(Покупки!$C$7:$C$18,$F30)>0,"есть в Покупках","")))) | P30: =IF($C30="","",DATE(YEAR($C30),MONTH($C30),1)) | Q30: =IF(ISNUMBER($G30),ABS($G30),0) | R30: =IF(AND($D30="Расход",COUNTIFS(Счета!$B$10:$B$21,$H30,Счета!$C$10:$C$21,"Кредитная")>0),1,0) | S30: =IF(21<=$S$9,DATE(YEAR($S$8),MONTH($S$8),21),"")
B31: =IF(AND($C31="",$F31=""),"",ROW()-9) | J31: =IF($C31="","",INDEX(Настройки!$V$6:$V$17,MONTH($C31))&" "&YEAR($C31)) | K31: =IF(OR($F31="",$D31="Перевод"),"",IF(AND(N($G31)<>0,COUNTIFS(Журнал!$C$10:$C$1509,$C31,Журнал!$P$10:$P$1509,$G31)>0),"есть в Журнале",IF(COUNTIF(Постоянные!$C$8:$C$37,$F31)>0,"есть в Постоянных",IF(COUNTIF(Покупки!$C$7:$C$18,$F31)>0,"есть в Покупках","")))) | P31: =IF($C31="","",DATE(YEAR($C31),MONTH($C31),1)) | Q31: =IF(ISNUMBER($G31),ABS($G31),0) | R31: =IF(AND($D31="Расход",COUNTIFS(Счета!$B$10:$B$21,$H31,Счета!$C$10:$C$21,"Кредитная")>0),1,0) | S31: =IF(22<=$S$9,DATE(YEAR($S$8),MONTH($S$8),22),"")
B32: =IF(AND($C32="",$F32=""),"",ROW()-9) | J32: =IF($C32="","",INDEX(Настройки!$V$6:$V$17,MONTH($C32))&" "&YEAR($C32)) | K32: =IF(OR($F32="",$D32="Перевод"),"",IF(AND(N($G32)<>0,COUNTIFS(Журнал!$C$10:$C$1509,$C32,Журнал!$P$10:$P$1509,$G32)>0),"есть в Журнале",IF(COUNTIF(Постоянные!$C$8:$C$37,$F32)>0,"есть в Постоянных",IF(COUNTIF(Покупки!$C$7:$C$18,$F32)>0,"есть в Покупках","")))) | P32: =IF($C32="","",DATE(YEAR($C32),MONTH($C32),1)) | Q32: =IF(ISNUMBER($G32),ABS($G32),0) | R32: =IF(AND($D32="Расход",COUNTIFS(Счета!$B$10:$B$21,$H32,Счета!$C$10:$C$21,"Кредитная")>0),1,0) | S32: =IF(23<=$S$9,DATE(YEAR($S$8),MONTH($S$8),23),"")
B33: =IF(AND($C33="",$F33=""),"",ROW()-9) | J33: =IF($C33="","",INDEX(Настройки!$V$6:$V$17,MONTH($C33))&" "&YEAR($C33)) | K33: =IF(OR($F33="",$D33="Перевод"),"",IF(AND(N($G33)<>0,COUNTIFS(Журнал!$C$10:$C$1509,$C33,Журнал!$P$10:$P$1509,$G33)>0),"есть в Журнале",IF(COUNTIF(Постоянные!$C$8:$C$37,$F33)>0,"есть в Постоянных",IF(COUNTIF(Покупки!$C$7:$C$18,$F33)>0,"есть в Покупках","")))) | P33: =IF($C33="","",DATE(YEAR($C33),MONTH($C33),1)) | Q33: =IF(ISNUMBER($G33),ABS($G33),0) | R33: =IF(AND($D33="Расход",COUNTIFS(Счета!$B$10:$B$21,$H33,Счета!$C$10:$C$21,"Кредитная")>0),1,0) | S33: =IF(24<=$S$9,DATE(YEAR($S$8),MONTH($S$8),24),"")
B34: =IF(AND($C34="",$F34=""),"",ROW()-9) | J34: =IF($C34="","",INDEX(Настройки!$V$6:$V$17,MONTH($C34))&" "&YEAR($C34)) | K34: =IF(OR($F34="",$D34="Перевод"),"",IF(AND(N($G34)<>0,COUNTIFS(Журнал!$C$10:$C$1509,$C34,Журнал!$P$10:$P$1509,$G34)>0),"есть в Журнале",IF(COUNTIF(Постоянные!$C$8:$C$37,$F34)>0,"есть в Постоянных",IF(COUNTIF(Покупки!$C$7:$C$18,$F34)>0,"есть в Покупках","")))) | P34: =IF($C34="","",DATE(YEAR($C34),MONTH($C34),1)) | Q34: =IF(ISNUMBER($G34),ABS($G34),0) | R34: =IF(AND($D34="Расход",COUNTIFS(Счета!$B$10:$B$21,$H34,Счета!$C$10:$C$21,"Кредитная")>0),1,0) | S34: =IF(25<=$S$9,DATE(YEAR($S$8),MONTH($S$8),25),"")
B35: =IF(AND($C35="",$F35=""),"",ROW()-9) | J35: =IF($C35="","",INDEX(Настройки!$V$6:$V$17,MONTH($C35))&" "&YEAR($C35)) | K35: =IF(OR($F35="",$D35="Перевод"),"",IF(AND(N($G35)<>0,COUNTIFS(Журнал!$C$10:$C$1509,$C35,Журнал!$P$10:$P$1509,$G35)>0),"есть в Журнале",IF(COUNTIF(Постоянные!$C$8:$C$37,$F35)>0,"есть в Постоянных",IF(COUNTIF(Покупки!$C$7:$C$18,$F35)>0,"есть в Покупках","")))) | P35: =IF($C35="","",DATE(YEAR($C35),MONTH($C35),1)) | Q35: =IF(ISNUMBER($G35),ABS($G35),0) | R35: =IF(AND($D35="Расход",COUNTIFS(Счета!$B$10:$B$21,$H35,Счета!$C$10:$C$21,"Кредитная")>0),1,0) | S35: =IF(26<=$S$9,DATE(YEAR($S$8),MONTH($S$8),26),"")
B36: =IF(AND($C36="",$F36=""),"",ROW()-9) | J36: =IF($C36="","",INDEX(Настройки!$V$6:$V$17,MONTH($C36))&" "&YEAR($C36)) | K36: =IF(OR($F36="",$D36="Перевод"),"",IF(AND(N($G36)<>0,COUNTIFS(Журнал!$C$10:$C$1509,$C36,Журнал!$P$10:$P$1509,$G36)>0),"есть в Журнале",IF(COUNTIF(Постоянные!$C$8:$C$37,$F36)>0,"есть в Постоянных",IF(COUNTIF(Покупки!$C$7:$C$18,$F36)>0,"есть в Покупках","")))) | P36: =IF($C36="","",DATE(YEAR($C36),MONTH($C36),1)) | Q36: =IF(ISNUMBER($G36),ABS($G36),0) | R36: =IF(AND($D36="Расход",COUNTIFS(Счета!$B$10:$B$21,$H36,Счета!$C$10:$C$21,"Кредитная")>0),1,0) | S36: =IF(27<=$S$9,DATE(YEAR($S$8),MONTH($S$8),27),"")
B37: =IF(AND($C37="",$F37=""),"",ROW()-9) | J37: =IF($C37="","",INDEX(Настройки!$V$6:$V$17,MONTH($C37))&" "&YEAR($C37)) | K37: =IF(OR($F37="",$D37="Перевод"),"",IF(AND(N($G37)<>0,COUNTIFS(Журнал!$C$10:$C$1509,$C37,Журнал!$P$10:$P$1509,$G37)>0),"есть в Журнале",IF(COUNTIF(Постоянные!$C$8:$C$37,$F37)>0,"есть в Постоянных",IF(COUNTIF(Покупки!$C$7:$C$18,$F37)>0,"есть в Покупках","")))) | P37: =IF($C37="","",DATE(YEAR($C37),MONTH($C37),1)) | Q37: =IF(ISNUMBER($G37),ABS($G37),0) | R37: =IF(AND($D37="Расход",COUNTIFS(Счета!$B$10:$B$21,$H37,Счета!$C$10:$C$21,"Кредитная")>0),1,0) | S37: =IF(28<=$S$9,DATE(YEAR($S$8),MONTH($S$8),28),"")
B38: =IF(AND($C38="",$F38=""),"",ROW()-9) | J38: =IF($C38="","",INDEX(Настройки!$V$6:$V$17,MONTH($C38))&" "&YEAR($C38)) | K38: =IF(OR($F38="",$D38="Перевод"),"",IF(AND(N($G38)<>0,COUNTIFS(Журнал!$C$10:$C$1509,$C38,Журнал!$P$10:$P$1509,$G38)>0),"есть в Журнале",IF(COUNTIF(Постоянные!$C$8:$C$37,$F38)>0,"есть в Постоянных",IF(COUNTIF(Покупки!$C$7:$C$18,$F38)>0,"есть в Покупках","")))) | P38: =IF($C38="","",DATE(YEAR($C38),MONTH($C38),1)) | Q38: =IF(ISNUMBER($G38),ABS($G38),0) | R38: =IF(AND($D38="Расход",COUNTIFS(Счета!$B$10:$B$21,$H38,Счета!$C$10:$C$21,"Кредитная")>0),1,0) | S38: =IF(29<=$S$9,DATE(YEAR($S$8),MONTH($S$8),29),"")
B39: =IF(AND($C39="",$F39=""),"",ROW()-9) | J39: =IF($C39="","",INDEX(Настройки!$V$6:$V$17,MONTH($C39))&" "&YEAR($C39)) | K39: =IF(OR($F39="",$D39="Перевод"),"",IF(AND(N($G39)<>0,COUNTIFS(Журнал!$C$10:$C$1509,$C39,Журнал!$P$10:$P$1509,$G39)>0),"есть в Журнале",IF(COUNTIF(Постоянные!$C$8:$C$37,$F39)>0,"есть в Постоянных",IF(COUNTIF(Покупки!$C$7:$C$18,$F39)>0,"есть в Покупках","")))) | P39: =IF($C39="","",DATE(YEAR($C39),MONTH($C39),1)) | Q39: =IF(ISNUMBER($G39),ABS($G39),0) | R39: =IF(AND($D39="Расход",COUNTIFS(Счета!$B$10:$B$21,$H39,Счета!$C$10:$C$21,"Кредитная")>0),1,0) | S39: =IF(30<=$S$9,DATE(YEAR($S$8),MONTH($S$8),30),"")
B40: =IF(AND($C40="",$F40=""),"",ROW()-9) | J40: =IF($C40="","",INDEX(Настройки!$V$6:$V$17,MONTH($C40))&" "&YEAR($C40)) | K40: =IF(OR($F40="",$D40="Перевод"),"",IF(AND(N($G40)<>0,COUNTIFS(Журнал!$C$10:$C$1509,$C40,Журнал!$P$10:$P$1509,$G40)>0),"есть в Журнале",IF(COUNTIF(Постоянные!$C$8:$C$37,$F40)>0,"есть в Постоянных",IF(COUNTIF(Покупки!$C$7:$C$18,$F40)>0,"есть в Покупках","")))) | P40: =IF($C40="","",DATE(YEAR($C40),MONTH($C40),1)) | Q40: =IF(ISNUMBER($G40),ABS($G40),0) | R40: =IF(AND($D40="Расход",COUNTIFS(Счета!$B$10:$B$21,$H40,Счета!$C$10:$C$21,"Кредитная")>0),1,0) | S40: =IF(31<=$S$9,DATE(YEAR($S$8),MONTH($S$8),31),"")
B41: =IF(AND($C41="",$F41=""),"",ROW()-9) | J41: =IF($C41="","",INDEX(Настройки!$V$6:$V$17,MONTH($C41))&" "&YEAR($C41)) | K41: =IF(OR($F41="",$D41="Перевод"),"",IF(AND(N($G41)<>0,COUNTIFS(Журнал!$C$10:$C$1509,$C41,Журнал!$P$10:$P$1509,$G41)>0),"есть в Журнале",IF(COUNTIF(Постоянные!$C$8:$C$37,$F41)>0,"есть в Постоянных",IF(COUNTIF(Покупки!$C$7:$C$18,$F41)>0,"есть в Покупках","")))) | P41: =IF($C41="","",DATE(YEAR($C41),MONTH($C41),1)) | Q41: =IF(ISNUMBER($G41),ABS($G41),0) | R41: =IF(AND($D41="Расход",COUNTIFS(Счета!$B$10:$B$21,$H41,Счета!$C$10:$C$21,"Кредитная")>0),1,0)
B42: =IF(AND($C42="",$F42=""),"",ROW()-9) | J42: =IF($C42="","",INDEX(Настройки!$V$6:$V$17,MONTH($C42))&" "&YEAR($C42)) | K42: =IF(OR($F42="",$D42="Перевод"),"",IF(AND(N($G42)<>0,COUNTIFS(Журнал!$C$10:$C$1509,$C42,Журнал!$P$10:$P$1509,$G42)>0),"есть в Журнале",IF(COUNTIF(Постоянные!$C$8:$C$37,$F42)>0,"есть в Постоянных",IF(COUNTIF(Покупки!$C$7:$C$18,$F42)>0,"есть в Покупках","")))) | P42: =IF($C42="","",DATE(YEAR($C42),MONTH($C42),1)) | Q42: =IF(ISNUMBER($G42),ABS($G42),0) | R42: =IF(AND($D42="Расход",COUNTIFS(Счета!$B$10:$B$21,$H42,Счета!$C$10:$C$21,"Кредитная")>0),1,0)
...

Sheet Счета
B2: Счета
B3: Сколько денег на каждой карте, в наличных и сколько долга по кредитке
B4: Остатки на дату | C4: =Настройки!$F$8 | D4: с этой даты в остатки идут все операции, отметки и покупки | Y4: =TODAY()
C5: На картах | E5: Наличные | G5: Долг по кредитке | I5: Всего (за вычетом долга)
C6: =SUMIFS($H$10:$H$21,$C$10:$C$21,"Дебетовая")+SUMIFS($H$10:$H$21,$C$10:$C$21,"Сберегательная") | E6: =SUMIFS($H$10:$H$21,$C$10:$C$21,"Наличные") | G6: =SUM($I$10:$I$21) | I6: =SUM($H$10:$H$21)
B9: Счёт | C9: Тип | D9: На начало | E9: Поступления | F9: Траты | G9: Переводы | H9: Сейчас | I9: Долг
B10: =IF(Настройки!$N$6="","",Настройки!$N$6) | C10: Дебетовая | D10: 1000 | E10: =IF($B10="","",SUMIFS(Операции!$Q$10:$Q$1009,Операции!$D$10:$D$1009,"Доход",Операции!$H$10:$H$1009,$B10,Операции!$C$10:$C$1009,">="&$C$4)+SUMIFS(Журнал!$P$10:$P$1509,Журнал!$D$10:$D$1509,"Доход",Журнал!$J$10:$J$1509,$B10,Журнал!$R$10:$R$1509,">="&DATE(YEAR($C$4),MONTH($C$4),1))+SUMIFS(Постоянные!$AC$8:$AC$367,Постоянные!$Z$8:$Z$367,"Доход",Постоянные!$AE$8:$AE$367,$B10,Постоянные!$Y$8:$Y$367,">="&$C$4)) | F10: =IF($B10="","",SUMIFS(Операции!$Q$10:$Q$1009,Операции!$D$10:$D$1009,"Расход",Операции!$H$10:$H$1009,$B10,Операции!$C$10:$C$1009,">="&$C$4)+SUMIFS(Журнал!$P$10:$P$1509,Журнал!$D$10:$D$1509,"<>Доход",Журнал!$J$10:$J$1509,$B10,Журнал!$R$10:$R$1509,">="&DATE(YEAR($C$4),MONTH($C$4),1))+SUMIFS(Постоянные!$AC$8:$AC$367,Постоянные!$Z$8:$Z$367,"Расход",Постоянные!$AE$8:$AE$367,$B10,Постоянные!$Y$8:$Y$367,">="&$C$4)+SUMIFS(Покупки!$S$7:$S$18,Покупки!$P$7:$P$18,$B10)-SUMIFS(Покупки!$S$7:$S$18,Покупки!$P$7:$P$18,$B10,Покупки!$G$7:$G$18,"<"&$C$4)) | G10: =IF($B10="","",SUMIFS(Операции!$Q$10:$Q$1009,Операции!$D$10:$D$1009,"Перевод",Операции!$I$10:$I$1009,$B10,Операции!$C$10:$C$1009,">="&$C$4)-SUMIFS(Операции!$Q$10:$Q$1009,Операции!$D$10:$D$1009,"Перевод",Операции!$H$10:$H$1009,$B10,Операции!$C$10:$C$1009,">="&$C$4)+IF($B10=$C$32,SUM($Y$39:$Y$50),0)-IF($B10=$C$34,SUM($Y$39:$Y$50),0)) | H10: =IF($B10="","",N($D10)+$E10-$F10+$G10) | I10: =IF(AND($C10="Кредитная",N($H10)<0),$H10,"")
B11: =IF(Настройки!$N$7="","",Настройки!$N$7) | C11: Наличные | D11: 0 | E11: =IF($B11="","",SUMIFS(Операции!$Q$10:$Q$1009,Операции!$D$10:$D$1009,"Доход",Операции!$H$10:$H$1009,$B11,Операции!$C$10:$C$1009,">="&$C$4)+SUMIFS(Журнал!$P$10:$P$1509,Журнал!$D$10:$D$1509,"Доход",Журнал!$J$10:$J$1509,$B11,Журнал!$R$10:$R$1509,">="&DATE(YEAR($C$4),MONTH($C$4),1))+SUMIFS(Постоянные!$AC$8:$AC$367,Постоянные!$Z$8:$Z$367,"Доход",Постоянные!$AE$8:$AE$367,$B11,Постоянные!$Y$8:$Y$367,">="&$C$4)) | F11: =IF($B11="","",SUMIFS(Операции!$Q$10:$Q$1009,Операции!$D$10:$D$1009,"Расход",Операции!$H$10:$H$1009,$B11,Операции!$C$10:$C$1009,">="&$C$4)+SUMIFS(Журнал!$P$10:$P$1509,Журнал!$D$10:$D$1509,"<>Доход",Журнал!$J$10:$J$1509,$B11,Журнал!$R$10:$R$1509,">="&DATE(YEAR($C$4),MONTH($C$4),1))+SUMIFS(Постоянные!$AC$8:$AC$367,Постоянные!$Z$8:$Z$367,"Расход",Постоянные!$AE$8:$AE$367,$B11,Постоянные!$Y$8:$Y$367,">="&$C$4)+SUMIFS(Покупки!$S$7:$S$18,Покупки!$P$7:$P$18,$B11)-SUMIFS(Покупки!$S$7:$S$18,Покупки!$P$7:$P$18,$B11,Покупки!$G$7:$G$18,"<"&$C$4)) | G11: =IF($B11="","",SUMIFS(Операции!$Q$10:$Q$1009,Операции!$D$10:$D$1009,"Перевод",Операции!$I$10:$I$1009,$B11,Операции!$C$10:$C$1009,">="&$C$4)-SUMIFS(Операции!$Q$10:$Q$1009,Операции!$D$10:$D$1009,"Перевод",Операции!$H$10:$H$1009,$B11,Операции!$C$10:$C$1009,">="&$C$4)+IF($B11=$C$32,SUM($Y$39:$Y$50),0)-IF($B11=$C$34,SUM($Y$39:$Y$50),0)) | H11: =IF($B11="","",N($D11)+$E11-$F11+$G11) | I11: =IF(AND($C11="Кредитная",N($H11)<0),$H11,"")
B12: =IF(Настройки!$N$8="","",Настройки!$N$8) | C12: Кредитная | D12: 0 | E12: =IF($B12="","",SUMIFS(Операции!$Q$10:$Q$1009,Операции!$D$10:$D$1009,"Доход",Операции!$H$10:$H$1009,$B12,Операции!$C$10:$C$1009,">="&$C$4)+SUMIFS(Журнал!$P$10:$P$1509,Журнал!$D$10:$D$1509,"Доход",Журнал!$J$10:$J$1509,$B12,Журнал!$R$10:$R$1509,">="&DATE(YEAR($C$4),MONTH($C$4),1))+SUMIFS(Постоянные!$AC$8:$AC$367,Постоянные!$Z$8:$Z$367,"Доход",Постоянные!$AE$8:$AE$367,$B12,Постоянные!$Y$8:$Y$367,">="&$C$4)) | F12: =IF($B12="","",SUMIFS(Операции!$Q$10:$Q$1009,Операции!$D$10:$D$1009,"Расход",Операции!$H$10:$H$1009,$B12,Операции!$C$10:$C$1009,">="&$C$4)+SUMIFS(Журнал!$P$10:$P$1509,Журнал!$D$10:$D$1509,"<>Доход",Журнал!$J$10:$J$1509,$B12,Журнал!$R$10:$R$1509,">="&DATE(YEAR($C$4),MONTH($C$4),1))+SUMIFS(Постоянные!$AC$8:$AC$367,Постоянные!$Z$8:$Z$367,"Расход",Постоянные!$AE$8:$AE$367,$B12,Постоянные!$Y$8:$Y$367,">="&$C$4)+SUMIFS(Покупки!$S$7:$S$18,Покупки!$P$7:$P$18,$B12)-SUMIFS(Покупки!$S$7:$S$18,Покупки!$P$7:$P$18,$B12,Покупки!$G$7:$G$18,"<"&$C$4)) | G12: =IF($B12="","",SUMIFS(Операции!$Q$10:$Q$1009,Операции!$D$10:$D$1009,"Перевод",Операции!$I$10:$I$1009,$B12,Операции!$C$10:$C$1009,">="&$C$4)-SUMIFS(Операции!$Q$10:$Q$1009,Операции!$D$10:$D$1009,"Перевод",Операции!$H$10:$H$1009,$B12,Операции!$C$10:$C$1009,">="&$C$4)+IF($B12=$C$32,SUM($Y$39:$Y$50),0)-IF($B12=$C$34,SUM($Y$39:$Y$50),0)) | H12: =IF($B12="","",N($D12)+$E12-$F12+$G12) | I12: =IF(AND($C12="Кредитная",N($H12)<0),$H12,"")
B13: =IF(Настройки!$N$9="","",Настройки!$N$9) | E13: =IF($B13="","",SUMIFS(Операции!$Q$10:$Q$1009,Операции!$D$10:$D$1009,"Доход",Операции!$H$10:$H$1009,$B13,Операции!$C$10:$C$1009,">="&$C$4)+SUMIFS(Журнал!$P$10:$P$1509,Журнал!$D$10:$D$1509,"Доход",Журнал!$J$10:$J$1509,$B13,Журнал!$R$10:$R$1509,">="&DATE(YEAR($C$4),MONTH($C$4),1))+SUMIFS(Постоянные!$AC$8:$AC$367,Постоянные!$Z$8:$Z$367,"Доход",Постоянные!$AE$8:$AE$367,$B13,Постоянные!$Y$8:$Y$367,">="&$C$4)) | F13: =IF($B13="","",SUMIFS(Операции!$Q$10:$Q$1009,Операции!$D$10:$D$1009,"Расход",Операции!$H$10:$H$1009,$B13,Операции!$C$10:$C$1009,">="&$C$4)+SUMIFS(Журнал!$P$10:$P$1509,Журнал!$D$10:$D$1509,"<>Доход",Журнал!$J$10:$J$1509,$B13,Журнал!$R$10:$R$1509,">="&DATE(YEAR($C$4),MONTH($C$4),1))+SUMIFS(Постоянные!$AC$8:$AC$367,Постоянные!$Z$8:$Z$367,"Расход",Постоянные!$AE$8:$AE$367,$B13,Постоянные!$Y$8:$Y$367,">="&$C$4)+SUMIFS(Покупки!$S$7:$S$18,Покупки!$P$7:$P$18,$B13)-SUMIFS(Покупки!$S$7:$S$18,Покупки!$P$7:$P$18,$B13,Покупки!$G$7:$G$18,"<"&$C$4)) | G13: =IF($B13="","",SUMIFS(Операции!$Q$10:$Q$1009,Операции!$D$10:$D$1009,"Перевод",Операции!$I$10:$I$1009,$B13,Операции!$C$10:$C$1009,">="&$C$4)-SUMIFS(Операции!$Q$10:$Q$1009,Операции!$D$10:$D$1009,"Перевод",Операции!$H$10:$H$1009,$B13,Операции!$C$10:$C$1009,">="&$C$4)+IF($B13=$C$32,SUM($Y$39:$Y$50),0)-IF($B13=$C$34,SUM($Y$39:$Y$50),0)) | H13: =IF($B13="","",N($D13)+$E13-$F13+$G13) | I13: =IF(AND($C13="Кредитная",N($H13)<0),$H13,"")
B14: =IF(Настройки!$N$10="","",Настройки!$N$10) | E14: =IF($B14="","",SUMIFS(Операции!$Q$10:$Q$1009,Операции!$D$10:$D$1009,"Доход",Операции!$H$10:$H$1009,$B14,Операции!$C$10:$C$1009,">="&$C$4)+SUMIFS(Журнал!$P$10:$P$1509,Журнал!$D$10:$D$1509,"Доход",Журнал!$J$10:$J$1509,$B14,Журнал!$R$10:$R$1509,">="&DATE(YEAR($C$4),MONTH($C$4),1))+SUMIFS(Постоянные!$AC$8:$AC$367,Постоянные!$Z$8:$Z$367,"Доход",Постоянные!$AE$8:$AE$367,$B14,Постоянные!$Y$8:$Y$367,">="&$C$4)) | F14: =IF($B14="","",SUMIFS(Операции!$Q$10:$Q$1009,Операции!$D$10:$D$1009,"Расход",Операции!$H$10:$H$1009,$B14,Операции!$C$10:$C$1009,">="&$C$4)+SUMIFS(Журнал!$P$10:$P$1509,Журнал!$D$10:$D$1509,"<>Доход",Журнал!$J$10:$J$1509,$B14,Журнал!$R$10:$R$1509,">="&DATE(YEAR($C$4),MONTH($C$4),1))+SUMIFS(Постоянные!$AC$8:$AC$367,Постоянные!$Z$8:$Z$367,"Расход",Постоянные!$AE$8:$AE$367,$B14,Постоянные!$Y$8:$Y$367,">="&$C$4)+SUMIFS(Покупки!$S$7:$S$18,Покупки!$P$7:$P$18,$B14)-SUMIFS(Покупки!$S$7:$S$18,Покупки!$P$7:$P$18,$B14,Покупки!$G$7:$G$18,"<"&$C$4)) | G14: =IF($B14="","",SUMIFS(Операции!$Q$10:$Q$1009,Операции!$D$10:$D$1009,"Перевод",Операции!$I$10:$I$1009,$B14,Операции!$C$10:$C$1009,">="&$C$4)-SUMIFS(Операции!$Q$10:$Q$1009,Операции!$D$10:$D$1009,"Перевод",Операции!$H$10:$H$1009,$B14,Операции!$C$10:$C$1009,">="&$C$4)+IF($B14=$C$32,SUM($Y$39:$Y$50),0)-IF($B14=$C$34,SUM($Y$39:$Y$50),0)) | H14: =IF($B14="","",N($D14)+$E14-$F14+$G14) | I14: =IF(AND($C14="Кредитная",N($H14)<0),$H14,"")
B15: =IF(Настройки!$N$11="","",Настройки!$N$11) | E15: =IF($B15="","",SUMIFS(Операции!$Q$10:$Q$1009,Операции!$D$10:$D$1009,"Доход",Операции!$H$10:$H$1009,$B15,Операции!$C$10:$C$1009,">="&$C$4)+SUMIFS(Журнал!$P$10:$P$1509,Журнал!$D$10:$D$1509,"Доход",Журнал!$J$10:$J$1509,$B15,Журнал!$R$10:$R$1509,">="&DATE(YEAR($C$4),MONTH($C$4),1))+SUMIFS(Постоянные!$AC$8:$AC$367,Постоянные!$Z$8:$Z$367,"Доход",Постоянные!$AE$8:$AE$367,$B15,Постоянные!$Y$8:$Y$367,">="&$C$4)) | F15: =IF($B15="","",SUMIFS(Операции!$Q$10:$Q$1009,Операции!$D$10:$D$1009,"Расход",Операции!$H$10:$H$1009,$B15,Операции!$C$10:$C$1009,">="&$C$4)+SUMIFS(Журнал!$P$10:$P$1509,Журнал!$D$10:$D$1509,"<>Доход",Журнал!$J$10:$J$1509,$B15,Журнал!$R$10:$R$1509,">="&DATE(YEAR($C$4),MONTH($C$4),1))+SUMIFS(Постоянные!$AC$8:$AC$367,Постоянные!$Z$8:$Z$367,"Расход",Постоянные!$AE$8:$AE$367,$B15,Постоянные!$Y$8:$Y$367,">="&$C$4)+SUMIFS(Покупки!$S$7:$S$18,Покупки!$P$7:$P$18,$B15)-SUMIFS(Покупки!$S$7:$S$18,Покупки!$P$7:$P$18,$B15,Покупки!$G$7:$G$18,"<"&$C$4)) | G15: =IF($B15="","",SUMIFS(Операции!$Q$10:$Q$1009,Операции!$D$10:$D$1009,"Перевод",Операции!$I$10:$I$1009,$B15,Операции!$C$10:$C$1009,">="&$C$4)-SUMIFS(Операции!$Q$10:$Q$1009,Операции!$D$10:$D$1009,"Перевод",Операции!$H$10:$H$1009,$B15,Операции!$C$10:$C$1009,">="&$C$4)+IF($B15=$C$32,SUM($Y$39:$Y$50),0)-IF($B15=$C$34,SUM($Y$39:$Y$50),0)) | H15: =IF($B15="","",N($D15)+$E15-$F15+$G15) | I15: =IF(AND($C15="Кредитная",N($H15)<0),$H15,"")
B16: =IF(Настройки!$N$12="","",Настройки!$N$12) | E16: =IF($B16="","",SUMIFS(Операции!$Q$10:$Q$1009,Операции!$D$10:$D$1009,"Доход",Операции!$H$10:$H$1009,$B16,Операции!$C$10:$C$1009,">="&$C$4)+SUMIFS(Журнал!$P$10:$P$1509,Журнал!$D$10:$D$1509,"Доход",Журнал!$J$10:$J$1509,$B16,Журнал!$R$10:$R$1509,">="&DATE(YEAR($C$4),MONTH($C$4),1))+SUMIFS(Постоянные!$AC$8:$AC$367,Постоянные!$Z$8:$Z$367,"Доход",Постоянные!$AE$8:$AE$367,$B16,Постоянные!$Y$8:$Y$367,">="&$C$4)) | F16: =IF($B16="","",SUMIFS(Операции!$Q$10:$Q$1009,Операции!$D$10:$D$1009,"Расход",Операции!$H$10:$H$1009,$B16,Операции!$C$10:$C$1009,">="&$C$4)+SUMIFS(Журнал!$P$10:$P$1509,Журнал!$D$10:$D$1509,"<>Доход",Журнал!$J$10:$J$1509,$B16,Журнал!$R$10:$R$1509,">="&DATE(YEAR($C$4),MONTH($C$4),1))+SUMIFS(Постоянные!$AC$8:$AC$367,Постоянные!$Z$8:$Z$367,"Расход",Постоянные!$AE$8:$AE$367,$B16,Постоянные!$Y$8:$Y$367,">="&$C$4)+SUMIFS(Покупки!$S$7:$S$18,Покупки!$P$7:$P$18,$B16)-SUMIFS(Покупки!$S$7:$S$18,Покупки!$P$7:$P$18,$B16,Покупки!$G$7:$G$18,"<"&$C$4)) | G16: =IF($B16="","",SUMIFS(Операции!$Q$10:$Q$1009,Операции!$D$10:$D$1009,"Перевод",Операции!$I$10:$I$1009,$B16,Операции!$C$10:$C$1009,">="&$C$4)-SUMIFS(Операции!$Q$10:$Q$1009,Операции!$D$10:$D$1009,"Перевод",Операции!$H$10:$H$1009,$B16,Операции!$C$10:$C$1009,">="&$C$4)+IF($B16=$C$32,SUM($Y$39:$Y$50),0)-IF($B16=$C$34,SUM($Y$39:$Y$50),0)) | H16: =IF($B16="","",N($D16)+$E16-$F16+$G16) | I16: =IF(AND($C16="Кредитная",N($H16)<0),$H16,"")
B17: =IF(Настройки!$N$13="","",Настройки!$N$13) | E17: =IF($B17="","",SUMIFS(Операции!$Q$10:$Q$1009,Операции!$D$10:$D$1009,"Доход",Операции!$H$10:$H$1009,$B17,Операции!$C$10:$C$1009,">="&$C$4)+SUMIFS(Журнал!$P$10:$P$1509,Журнал!$D$10:$D$1509,"Доход",Журнал!$J$10:$J$1509,$B17,Журнал!$R$10:$R$1509,">="&DATE(YEAR($C$4),MONTH($C$4),1))+SUMIFS(Постоянные!$AC$8:$AC$367,Постоянные!$Z$8:$Z$367,"Доход",Постоянные!$AE$8:$AE$367,$B17,Постоянные!$Y$8:$Y$367,">="&$C$4)) | F17: =IF($B17="","",SUMIFS(Операции!$Q$10:$Q$1009,Операции!$D$10:$D$1009,"Расход",Операции!$H$10:$H$1009,$B17,Операции!$C$10:$C$1009,">="&$C$4)+SUMIFS(Журнал!$P$10:$P$1509,Журнал!$D$10:$D$1509,"<>Доход",Журнал!$J$10:$J$1509,$B17,Журнал!$R$10:$R$1509,">="&DATE(YEAR($C$4),MONTH($C$4),1))+SUMIFS(Постоянные!$AC$8:$AC$367,Постоянные!$Z$8:$Z$367,"Расход",Постоянные!$AE$8:$AE$367,$B17,Постоянные!$Y$8:$Y$367,">="&$C$4)+SUMIFS(Покупки!$S$7:$S$18,Покупки!$P$7:$P$18,$B17)-SUMIFS(Покупки!$S$7:$S$18,Покупки!$P$7:$P$18,$B17,Покупки!$G$7:$G$18,"<"&$C$4)) | G17: =IF($B17="","",SUMIFS(Операции!$Q$10:$Q$1009,Операции!$D$10:$D$1009,"Перевод",Операции!$I$10:$I$1009,$B17,Операции!$C$10:$C$1009,">="&$C$4)-SUMIFS(Операции!$Q$10:$Q$1009,Операции!$D$10:$D$1009,"Перевод",Операции!$H$10:$H$1009,$B17,Операции!$C$10:$C$1009,">="&$C$4)+IF($B17=$C$32,SUM($Y$39:$Y$50),0)-IF($B17=$C$34,SUM($Y$39:$Y$50),0)) | H17: =IF($B17="","",N($D17)+$E17-$F17+$G17) | I17: =IF(AND($C17="Кредитная",N($H17)<0),$H17,"")
B18: =IF(Настройки!$N$14="","",Настройки!$N$14) | E18: =IF($B18="","",SUMIFS(Операции!$Q$10:$Q$1009,Операции!$D$10:$D$1009,"Доход",Операции!$H$10:$H$1009,$B18,Операции!$C$10:$C$1009,">="&$C$4)+SUMIFS(Журнал!$P$10:$P$1509,Журнал!$D$10:$D$1509,"Доход",Журнал!$J$10:$J$1509,$B18,Журнал!$R$10:$R$1509,">="&DATE(YEAR($C$4),MONTH($C$4),1))+SUMIFS(Постоянные!$AC$8:$AC$367,Постоянные!$Z$8:$Z$367,"Доход",Постоянные!$AE$8:$AE$367,$B18,Постоянные!$Y$8:$Y$367,">="&$C$4)) | F18: =IF($B18="","",SUMIFS(Операции!$Q$10:$Q$1009,Операции!$D$10:$D$1009,"Расход",Операции!$H$10:$H$1009,$B18,Операции!$C$10:$C$1009,">="&$C$4)+SUMIFS(Журнал!$P$10:$P$1509,Журнал!$D$10:$D$1509,"<>Доход",Журнал!$J$10:$J$1509,$B18,Журнал!$R$10:$R$1509,">="&DATE(YEAR($C$4),MONTH($C$4),1))+SUMIFS(Постоянные!$AC$8:$AC$367,Постоянные!$Z$8:$Z$367,"Расход",Постоянные!$AE$8:$AE$367,$B18,Постоянные!$Y$8:$Y$367,">="&$C$4)+SUMIFS(Покупки!$S$7:$S$18,Покупки!$P$7:$P$18,$B18)-SUMIFS(Покупки!$S$7:$S$18,Покупки!$P$7:$P$18,$B18,Покупки!$G$7:$G$18,"<"&$C$4)) | G18: =IF($B18="","",SUMIFS(Операции!$Q$10:$Q$1009,Операции!$D$10:$D$1009,"Перевод",Операции!$I$10:$I$1009,$B18,Операции!$C$10:$C$1009,">="&$C$4)-SUMIFS(Операции!$Q$10:$Q$1009,Операции!$D$10:$D$1009,"Перевод",Операции!$H$10:$H$1009,$B18,Операции!$C$10:$C$1009,">="&$C$4)+IF($B18=$C$32,SUM($Y$39:$Y$50),0)-IF($B18=$C$34,SUM($Y$39:$Y$50),0)) | H18: =IF($B18="","",N($D18)+$E18-$F18+$G18) | I18: =IF(AND($C18="Кредитная",N($H18)<0),$H18,"")
B19: =IF(Настройки!$N$15="","",Настройки!$N$15) | E19: =IF($B19="","",SUMIFS(Операции!$Q$10:$Q$1009,Операции!$D$10:$D$1009,"Доход",Операции!$H$10:$H$1009,$B19,Операции!$C$10:$C$1009,">="&$C$4)+SUMIFS(Журнал!$P$10:$P$1509,Журнал!$D$10:$D$1509,"Доход",Журнал!$J$10:$J$1509,$B19,Журнал!$R$10:$R$1509,">="&DATE(YEAR($C$4),MONTH($C$4),1))+SUMIFS(Постоянные!$AC$8:$AC$367,Постоянные!$Z$8:$Z$367,"Доход",Постоянные!$AE$8:$AE$367,$B19,Постоянные!$Y$8:$Y$367,">="&$C$4)) | F19: =IF($B19="","",SUMIFS(Операции!$Q$10:$Q$1009,Операции!$D$10:$D$1009,"Расход",Операции!$H$10:$H$1009,$B19,Операции!$C$10:$C$1009,">="&$C$4)+SUMIFS(Журнал!$P$10:$P$1509,Журнал!$D$10:$D$1509,"<>Доход",Журнал!$J$10:$J$1509,$B19,Журнал!$R$10:$R$1509,">="&DATE(YEAR($C$4),MONTH($C$4),1))+SUMIFS(Постоянные!$AC$8:$AC$367,Постоянные!$Z$8:$Z$367,"Расход",Постоянные!$AE$8:$AE$367,$B19,Постоянные!$Y$8:$Y$367,">="&$C$4)+SUMIFS(Покупки!$S$7:$S$18,Покупки!$P$7:$P$18,$B19)-SUMIFS(Покупки!$S$7:$S$18,Покупки!$P$7:$P$18,$B19,Покупки!$G$7:$G$18,"<"&$C$4)) | G19: =IF($B19="","",SUMIFS(Операции!$Q$10:$Q$1009,Операции!$D$10:$D$1009,"Перевод",Операции!$I$10:$I$1009,$B19,Операции!$C$10:$C$1009,">="&$C$4)-SUMIFS(Операции!$Q$10:$Q$1009,Операции!$D$10:$D$1009,"Перевод",Операции!$H$10:$H$1009,$B19,Операции!$C$10:$C$1009,">="&$C$4)+IF($B19=$C$32,SUM($Y$39:$Y$50),0)-IF($B19=$C$34,SUM($Y$39:$Y$50),0)) | H19: =IF($B19="","",N($D19)+$E19-$F19+$G19) | I19: =IF(AND($C19="Кредитная",N($H19)<0),$H19,"")
B20: =IF(Настройки!$N$16="","",Настройки!$N$16) | E20: =IF($B20="","",SUMIFS(Операции!$Q$10:$Q$1009,Операции!$D$10:$D$1009,"Доход",Операции!$H$10:$H$1009,$B20,Операции!$C$10:$C$1009,">="&$C$4)+SUMIFS(Журнал!$P$10:$P$1509,Журнал!$D$10:$D$1509,"Доход",Журнал!$J$10:$J$1509,$B20,Журнал!$R$10:$R$1509,">="&DATE(YEAR($C$4),MONTH($C$4),1))+SUMIFS(Постоянные!$AC$8:$AC$367,Постоянные!$Z$8:$Z$367,"Доход",Постоянные!$AE$8:$AE$367,$B20,Постоянные!$Y$8:$Y$367,">="&$C$4)) | F20: =IF($B20="","",SUMIFS(Операции!$Q$10:$Q$1009,Операции!$D$10:$D$1009,"Расход",Операции!$H$10:$H$1009,$B20,Операции!$C$10:$C$1009,">="&$C$4)+SUMIFS(Журнал!$P$10:$P$1509,Журнал!$D$10:$D$1509,"<>Доход",Журнал!$J$10:$J$1509,$B20,Журнал!$R$10:$R$1509,">="&DATE(YEAR($C$4),MONTH($C$4),1))+SUMIFS(Постоянные!$AC$8:$AC$367,Постоянные!$Z$8:$Z$367,"Расход",Постоянные!$AE$8:$AE$367,$B20,Постоянные!$Y$8:$Y$367,">="&$C$4)+SUMIFS(Покупки!$S$7:$S$18,Покупки!$P$7:$P$18,$B20)-SUMIFS(Покупки!$S$7:$S$18,Покупки!$P$7:$P$18,$B20,Покупки!$G$7:$G$18,"<"&$C$4)) | G20: =IF($B20="","",SUMIFS(Операции!$Q$10:$Q$1009,Операции!$D$10:$D$1009,"Перевод",Операции!$I$10:$I$1009,$B20,Операции!$C$10:$C$1009,">="&$C$4)-SUMIFS(Операции!$Q$10:$Q$1009,Операции!$D$10:$D$1009,"Перевод",Операции!$H$10:$H$1009,$B20,Операции!$C$10:$C$1009,">="&$C$4)+IF($B20=$C$32,SUM($Y$39:$Y$50),0)-IF($B20=$C$34,SUM($Y$39:$Y$50),0)) | H20: =IF($B20="","",N($D20)+$E20-$F20+$G20) | I20: =IF(AND($C20="Кредитная",N($H20)<0),$H20,"")
B21: =IF(Настройки!$N$17="","",Настройки!$N$17) | E21: =IF($B21="","",SUMIFS(Операции!$Q$10:$Q$1009,Операции!$D$10:$D$1009,"Доход",Операции!$H$10:$H$1009,$B21,Операции!$C$10:$C$1009,">="&$C$4)+SUMIFS(Журнал!$P$10:$P$1509,Журнал!$D$10:$D$1509,"Доход",Журнал!$J$10:$J$1509,$B21,Журнал!$R$10:$R$1509,">="&DATE(YEAR($C$4),MONTH($C$4),1))+SUMIFS(Постоянные!$AC$8:$AC$367,Постоянные!$Z$8:$Z$367,"Доход",Постоянные!$AE$8:$AE$367,$B21,Постоянные!$Y$8:$Y$367,">="&$C$4)) | F21: =IF($B21="","",SUMIFS(Операции!$Q$10:$Q$1009,Операции!$D$10:$D$1009,"Расход",Операции!$H$10:$H$1009,$B21,Операции!$C$10:$C$1009,">="&$C$4)+SUMIFS(Журнал!$P$10:$P$1509,Журнал!$D$10:$D$1509,"<>Доход",Журнал!$J$10:$J$1509,$B21,Журнал!$R$10:$R$1509,">="&DATE(YEAR($C$4),MONTH($C$4),1))+SUMIFS(Постоянные!$AC$8:$AC$367,Постоянные!$Z$8:$Z$367,"Расход",Постоянные!$AE$8:$AE$367,$B21,Постоянные!$Y$8:$Y$367,">="&$C$4)+SUMIFS(Покупки!$S$7:$S$18,Покупки!$P$7:$P$18,$B21)-SUMIFS(Покупки!$S$7:$S$18,Покупки!$P$7:$P$18,$B21,Покупки!$G$7:$G$18,"<"&$C$4)) | G21: =IF($B21="","",SUMIFS(Операции!$Q$10:$Q$1009,Операции!$D$10:$D$1009,"Перевод",Операции!$I$10:$I$1009,$B21,Операции!$C$10:$C$1009,">="&$C$4)-SUMIFS(Операции!$Q$10:$Q$1009,Операции!$D$10:$D$1009,"Перевод",Операции!$H$10:$H$1009,$B21,Операции!$C$10:$C$1009,">="&$C$4)+IF($B21=$C$32,SUM($Y$39:$Y$50),0)-IF($B21=$C$34,SUM($Y$39:$Y$50),0)) | H21: =IF($B21="","",N($D21)+$E21-$F21+$G21) | I21: =IF(AND($C21="Кредитная",N($H21)<0),$H21,"")
B22: ИТОГО | D22: =SUM(D10:D21) | E22: =SUM(E10:E21) | F22: =SUM(F10:F21) | G22: =SUM(G10:G21) | H22: =SUM(H10:H21) | I22: =SUM(I10:I21)
B24: Проверка: всё ли попадает в остатки
B25: Оплачено без счёта — строк | D25: =COUNTIFS(Журнал!$P$10:$P$1509,"<>0",Журнал!$J$10:$J$1509,"")+COUNTIFS(Операции!$G$10:$G$1009,"<>",Операции!$H$10:$H$1009,"")+COUNTIFS(Постоянные!$AC$8:$AC$367,"<>0",Постоянные!$AE$8:$AE$367,"")+COUNTIFS(Покупки!$S$7:$S$18,"<>0",Покупки!$P$7:$P$18,"")
B26: …на сумму | D26: =SUMIFS(Журнал!$P$10:$P$1509,Журнал!$J$10:$J$1509,"")+SUMIFS(Операции!$Q$10:$Q$1009,Операции!$H$10:$H$1009,"")+SUMIFS(Постоянные!$AC$8:$AC$367,Постоянные!$AE$8:$AE$367,"")+SUMIFS(Покупки!$S$7:$S$18,Покупки!$P$7:$P$18,"")
B27: Переводов без «на счёт» | D27: =COUNTIFS(Операции!$D$10:$D$1009,"Перевод",Операции!$I$10:$I$1009,"")
B29: Долг по кредитке — со знаком минус (например −350). Снятие наличных и перевод между картами — в «Операциях», тип «Перевод»; погашение кредитки считается само (таблица ниже). Остаток «Сейчас» учитывает всё, что отмечено оплаченным, в том числе отметки на будущие даты.
B31: Кредитная карта: выписки и погашения
B32: Кредитная карта | C32: =IFERROR(INDEX($B$10:$B$21,MATCH("Кредитная",$C$10:$C$21,0)),"")
B33: Гасится автоматически | C33: Да
B34: Со счёта | C34: =Настройки!$N$6
B35: Выписка закрывается (число) | C35: 4
B36: Долг списывается (число) | C36: 10
B37: Ближайшее списание | C37: =IF((COUNTIF($H$39:$H$50,"<"&$Y$4)+1)>12,"—",INDEX($H$39:$H$50,(COUNTIF($H$39:$H$50,"<"&$Y$4)+1))) | D37: =IF((COUNTIF($H$39:$H$50,"<"&$Y$4)+1)>12,0,INDEX($I$39:$I$50,(COUNTIF($H$39:$H$50,"<"&$Y$4)+1))) | E37: =IF($C$33="Да","спишется со счёта «"&$C$34&"»","гасите вручную: «Операции», «Перевод»")
B38: Выписка на | C38: Долг с прошлой выписки | D38: Погашено | E38: Покупки | F38: Возвраты и переводы | G38: Долг по выписке | H38: Спишется | I38: Сумма списания
B39: =DATE(Настройки!$C$8,Настройки!$D$9+0,MAX(1,MIN(28,N($C$35)))) | C39: =IF($C$32="",0,MIN(0,SUMIFS($D$10:$D$21,$B$10:$B$21,$C$32))) | D39: =0 | E39: =IF($C$32="",0,-(SUMIFS(Операции!$Q$10:$Q$1009,Операции!$D$10:$D$1009,"Расход",Операции!$H$10:$H$1009,$C$32,Операции!$C$10:$C$1009,">="&$X39,Операции!$C$10:$C$1009,"<="&$B39)+SUMIFS(Журнал!$P$10:$P$1509,Журнал!$D$10:$D$1509,"<>Доход",Журнал!$J$10:$J$1509,$C$32,Журнал!$C$10:$C$1509,">="&$X39,Журнал!$C$10:$C$1509,"<="&$B39)+SUMIFS(Постоянные!$AC$8:$AC$367,Постоянные!$Z$8:$Z$367,"Расход",Постоянные!$AE$8:$AE$367,$C$32,Постоянные!$Y$8:$Y$367,">="&$X39,Постоянные!$Y$8:$Y$367,"<="&$B39)+SUMIFS(Покупки!$S$7:$S$18,Покупки!$P$7:$P$18,$C$32,Покупки!$G$7:$G$18,">="&$X39,Покупки!$G$7:$G$18,"<="&$B39))) | F39: =IF($C$32="",0,SUMIFS(Операции!$Q$10:$Q$1009,Операции!$D$10:$D$1009,"Доход",Операции!$H$10:$H$1009,$C$32,Операции!$C$10:$C$1009,">="&$X39,Операции!$C$10:$C$1009,"<="&$B39)+SUMIFS(Журнал!$P$10:$P$1509,Журнал!$D$10:$D$1509,"Доход",Журнал!$J$10:$J$1509,$C$32,Журнал!$C$10:$C$1509,">="&$X39,Журнал!$C$10:$C$1509,"<="&$B39)+SUMIFS(Постоянные!$AC$8:$AC$367,Постоянные!$Z$8:$Z$367,"Доход",Постоянные!$AE$8:$AE$367,$C$32,Постоянные!$Y$8:$Y$367,">="&$X39,Постоянные!$Y$8:$Y$367,"<="&$B39)+SUMIFS(Операции!$Q$10:$Q$1009,Операции!$D$10:$D$1009,"Перевод",Операции!$I$10:$I$1009,$C$32,Операции!$C$10:$C$1009,">="&$X39,Операции!$C$10:$C$1009,"<="&$B39)-SUMIFS(Операции!$Q$10:$Q$1009,Операции!$D$10:$D$1009,"Перевод",Операции!$H$10:$H$1009,$C$32,Операции!$C$10:$C$1009,">="&$X39,Операции!$C$10:$C$1009,"<="&$B39)) | G39: =C39+D39+E39+F39 | H39: =DATE(YEAR(B39),MONTH(B39),MAX(1,MIN(28,N($C$36)))) | I39: =IF($C$33="Да",-MIN(0,G39),0) | X39: =$C$4 | Y39: =IF(AND(H39<=$Y$4,H39>=$C$4),I39,0)
B40: =DATE(Настройки!$C$8,Настройки!$D$9+1,MAX(1,MIN(28,N($C$35)))) | C40: =G39 | D40: =I39 | E40: =IF($C$32="",0,-(SUMIFS(Операции!$Q$10:$Q$1009,Операции!$D$10:$D$1009,"Расход",Операции!$H$10:$H$1009,$C$32,Операции!$C$10:$C$1009,">="&$X40,Операции!$C$10:$C$1009,"<="&$B40)+SUMIFS(Журнал!$P$10:$P$1509,Журнал!$D$10:$D$1509,"<>Доход",Журнал!$J$10:$J$1509,$C$32,Журнал!$C$10:$C$1509,">="&$X40,Журнал!$C$10:$C$1509,"<="&$B40)+SUMIFS(Постоянные!$AC$8:$AC$367,Постоянные!$Z$8:$Z$367,"Расход",Постоянные!$AE$8:$AE$367,$C$32,Постоянные!$Y$8:$Y$367,">="&$X40,Постоянные!$Y$8:$Y$367,"<="&$B40)+SUMIFS(Покупки!$S$7:$S$18,Покупки!$P$7:$P$18,$C$32,Покупки!$G$7:$G$18,">="&$X40,Покупки!$G$7:$G$18,"<="&$B40))) | F40: =IF($C$32="",0,SUMIFS(Операции!$Q$10:$Q$1009,Операции!$D$10:$D$1009,"Доход",Операции!$H$10:$H$1009,$C$32,Операции!$C$10:$C$1009,">="&$X40,Операции!$C$10:$C$1009,"<="&$B40)+SUMIFS(Журнал!$P$10:$P$1509,Журнал!$D$10:$D$1509,"Доход",Журнал!$J$10:$J$1509,$C$32,Журнал!$C$10:$C$1509,">="&$X40,Журнал!$C$10:$C$1509,"<="&$B40)+SUMIFS(Постоянные!$AC$8:$AC$367,Постоянные!$Z$8:$Z$367,"Доход",Постоянные!$AE$8:$AE$367,$C$32,Постоянные!$Y$8:$Y$367,">="&$X40,Постоянные!$Y$8:$Y$367,"<="&$B40)+SUMIFS(Операции!$Q$10:$Q$1009,Операции!$D$10:$D$1009,"Перевод",Операции!$I$10:$I$1009,$C$32,Операции!$C$10:$C$1009,">="&$X40,Операции!$C$10:$C$1009,"<="&$B40)-SUMIFS(Операции!$Q$10:$Q$1009,Операции!$D$10:$D$1009,"Перевод",Операции!$H$10:$H$1009,$C$32,Операции!$C$10:$C$1009,">="&$X40,Операции!$C$10:$C$1009,"<="&$B40)) | G40: =C40+D40+E40+F40 | H40: =DATE(YEAR(B40),MONTH(B40),MAX(1,MIN(28,N($C$36)))) | I40: =IF($C$33="Да",-MIN(0,G40),0) | X40: =B39+1 | Y40: =IF(AND(H40<=$Y$4,H40>=$C$4),I40,0)
B41: =DATE(Настройки!$C$8,Настройки!$D$9+2,MAX(1,MIN(28,N($C$35)))) | C41: =G40 | D41: =I40 | E41: =IF($C$32="",0,-(SUMIFS(Операции!$Q$10:$Q$1009,Операции!$D$10:$D$1009,"Расход",Операции!$H$10:$H$1009,$C$32,Операции!$C$10:$C$1009,">="&$X41,Операции!$C$10:$C$1009,"<="&$B41)+SUMIFS(Журнал!$P$10:$P$1509,Журнал!$D$10:$D$1509,"<>Доход",Журнал!$J$10:$J$1509,$C$32,Журнал!$C$10:$C$1509,">="&$X41,Журнал!$C$10:$C$1509,"<="&$B41)+SUMIFS(Постоянные!$AC$8:$AC$367,Постоянные!$Z$8:$Z$367,"Расход",Постоянные!$AE$8:$AE$367,$C$32,Постоянные!$Y$8:$Y$367,">="&$X41,Постоянные!$Y$8:$Y$367,"<="&$B41)+SUMIFS(Покупки!$S$7:$S$18,Покупки!$P$7:$P$18,$C$32,Покупки!$G$7:$G$18,">="&$X41,Покупки!$G$7:$G$18,"<="&$B41))) | F41: =IF($C$32="",0,SUMIFS(Операции!$Q$10:$Q$1009,Операции!$D$10:$D$1009,"Доход",Операции!$H$10:$H$1009,$C$32,Операции!$C$10:$C$1009,">="&$X41,Операции!$C$10:$C$1009,"<="&$B41)+SUMIFS(Журнал!$P$10:$P$1509,Журнал!$D$10:$D$1509,"Доход",Журнал!$J$10:$J$1509,$C$32,Журнал!$C$10:$C$1509,">="&$X41,Журнал!$C$10:$C$1509,"<="&$B41)+SUMIFS(Постоянные!$AC$8:$AC$367,Постоянные!$Z$8:$Z$367,"Доход",Постоянные!$AE$8:$AE$367,$C$32,Постоянные!$Y$8:$Y$367,">="&$X41,Постоянные!$Y$8:$Y$367,"<="&$B41)+SUMIFS(Операции!$Q$10:$Q$1009,Операции!$D$10:$D$1009,"Перевод",Операции!$I$10:$I$1009,$C$32,Операции!$C$10:$C$1009,">="&$X41,Операции!$C$10:$C$1009,"<="&$B41)-SUMIFS(Операции!$Q$10:$Q$1009,Операции!$D$10:$D$1009,"Перевод",Операции!$H$10:$H$1009,$C$32,Операции!$C$10:$C$1009,">="&$X41,Операции!$C$10:$C$1009,"<="&$B41)) | G41: =C41+D41+E41+F41 | H41: =DATE(YEAR(B41),MONTH(B41),MAX(1,MIN(28,N($C$36)))) | I41: =IF($C$33="Да",-MIN(0,G41),0) | X41: =B40+1 | Y41: =IF(AND(H41<=$Y$4,H41>=$C$4),I41,0)
B42: =DATE(Настройки!$C$8,Настройки!$D$9+3,MAX(1,MIN(28,N($C$35)))) | C42: =G41 | D42: =I41 | E42: =IF($C$32="",0,-(SUMIFS(Операции!$Q$10:$Q$1009,Операции!$D$10:$D$1009,"Расход",Операции!$H$10:$H$1009,$C$32,Операции!$C$10:$C$1009,">="&$X42,Операции!$C$10:$C$1009,"<="&$B42)+SUMIFS(Журнал!$P$10:$P$1509,Журнал!$D$10:$D$1509,"<>Доход",Журнал!$J$10:$J$1509,$C$32,Журнал!$C$10:$C$1509,">="&$X42,Журнал!$C$10:$C$1509,"<="&$B42)+SUMIFS(Постоянные!$AC$8:$AC$367,Постоянные!$Z$8:$Z$367,"Расход",Постоянные!$AE$8:$AE$367,$C$32,Постоянные!$Y$8:$Y$367,">="&$X42,Постоянные!$Y$8:$Y$367,"<="&$B42)+SUMIFS(Покупки!$S$7:$S$18,Покупки!$P$7:$P$18,$C$32,Покупки!$G$7:$G$18,">="&$X42,Покупки!$G$7:$G$18,"<="&$B42))) | F42: =IF($C$32="",0,SUMIFS(Операции!$Q$10:$Q$1009,Операции!$D$10:$D$1009,"Доход",Операции!$H$10:$H$1009,$C$32,Операции!$C$10:$C$1009,">="&$X42,Операции!$C$10:$C$1009,"<="&$B42)+SUMIFS(Журнал!$P$10:$P$1509,Журнал!$D$10:$D$1509,"Доход",Журнал!$J$10:$J$1509,$C$32,Журнал!$C$10:$C$1509,">="&$X42,Журнал!$C$10:$C$1509,"<="&$B42)+SUMIFS(Постоянные!$AC$8:$AC$367,Постоянные!$Z$8:$Z$367,"Доход",Постоянные!$AE$8:$AE$367,$C$32,Постоянные!$Y$8:$Y$367,">="&$X42,Постоянные!$Y$8:$Y$367,"<="&$B42)+SUMIFS(Операции!$Q$10:$Q$1009,Операции!$D$10:$D$1009,"Перевод",Операции!$I$10:$I$1009,$C$32,Операции!$C$10:$C$1009,">="&$X42,Операции!$C$10:$C$1009,"<="&$B42)-SUMIFS(Операции!$Q$10:$Q$1009,Операции!$D$10:$D$1009,"Перевод",Операции!$H$10:$H$1009,$C$32,Операции!$C$10:$C$1009,">="&$X42,Операции!$C$10:$C$1009,"<="&$B42)) | G42: =C42+D42+E42+F42 | H42: =DATE(YEAR(B42),MONTH(B42),MAX(1,MIN(28,N($C$36)))) | I42: =IF($C$33="Да",-MIN(0,G42),0) | X42: =B41+1 | Y42: =IF(AND(H42<=$Y$4,H42>=$C$4),I42,0)
B43: =DATE(Настройки!$C$8,Настройки!$D$9+4,MAX(1,MIN(28,N($C$35)))) | C43: =G42 | D43: =I42 | E43: =IF($C$32="",0,-(SUMIFS(Операции!$Q$10:$Q$1009,Операции!$D$10:$D$1009,"Расход",Операции!$H$10:$H$1009,$C$32,Операции!$C$10:$C$1009,">="&$X43,Операции!$C$10:$C$1009,"<="&$B43)+SUMIFS(Журнал!$P$10:$P$1509,Журнал!$D$10:$D$1509,"<>Доход",Журнал!$J$10:$J$1509,$C$32,Журнал!$C$10:$C$1509,">="&$X43,Журнал!$C$10:$C$1509,"<="&$B43)+SUMIFS(Постоянные!$AC$8:$AC$367,Постоянные!$Z$8:$Z$367,"Расход",Постоянные!$AE$8:$AE$367,$C$32,Постоянные!$Y$8:$Y$367,">="&$X43,Постоянные!$Y$8:$Y$367,"<="&$B43)+SUMIFS(Покупки!$S$7:$S$18,Покупки!$P$7:$P$18,$C$32,Покупки!$G$7:$G$18,">="&$X43,Покупки!$G$7:$G$18,"<="&$B43))) | F43: =IF($C$32="",0,SUMIFS(Операции!$Q$10:$Q$1009,Операции!$D$10:$D$1009,"Доход",Операции!$H$10:$H$1009,$C$32,Операции!$C$10:$C$1009,">="&$X43,Операции!$C$10:$C$1009,"<="&$B43)+SUMIFS(Журнал!$P$10:$P$1509,Журнал!$D$10:$D$1509,"Доход",Журнал!$J$10:$J$1509,$C$32,Журнал!$C$10:$C$1509,">="&$X43,Журнал!$C$10:$C$1509,"<="&$B43)+SUMIFS(Постоянные!$AC$8:$AC$367,Постоянные!$Z$8:$Z$367,"Доход",Постоянные!$AE$8:$AE$367,$C$32,Постоянные!$Y$8:$Y$367,">="&$X43,Постоянные!$Y$8:$Y$367,"<="&$B43)+SUMIFS(Операции!$Q$10:$Q$1009,Операции!$D$10:$D$1009,"Перевод",Операции!$I$10:$I$1009,$C$32,Операции!$C$10:$C$1009,">="&$X43,Операции!$C$10:$C$1009,"<="&$B43)-SUMIFS(Операции!$Q$10:$Q$1009,Операции!$D$10:$D$1009,"Перевод",Операции!$H$10:$H$1009,$C$32,Операции!$C$10:$C$1009,">="&$X43,Операции!$C$10:$C$1009,"<="&$B43)) | G43: =C43+D43+E43+F43 | H43: =DATE(YEAR(B43),MONTH(B43),MAX(1,MIN(28,N($C$36)))) | I43: =IF($C$33="Да",-MIN(0,G43),0) | X43: =B42+1 | Y43: =IF(AND(H43<=$Y$4,H43>=$C$4),I43,0)
B44: =DATE(Настройки!$C$8,Настройки!$D$9+5,MAX(1,MIN(28,N($C$35)))) | C44: =G43 | D44: =I43 | E44: =IF($C$32="",0,-(SUMIFS(Операции!$Q$10:$Q$1009,Операции!$D$10:$D$1009,"Расход",Операции!$H$10:$H$1009,$C$32,Операции!$C$10:$C$1009,">="&$X44,Операции!$C$10:$C$1009,"<="&$B44)+SUMIFS(Журнал!$P$10:$P$1509,Журнал!$D$10:$D$1509,"<>Доход",Журнал!$J$10:$J$1509,$C$32,Журнал!$C$10:$C$1509,">="&$X44,Журнал!$C$10:$C$1509,"<="&$B44)+SUMIFS(Постоянные!$AC$8:$AC$367,Постоянные!$Z$8:$Z$367,"Расход",Постоянные!$AE$8:$AE$367,$C$32,Постоянные!$Y$8:$Y$367,">="&$X44,Постоянные!$Y$8:$Y$367,"<="&$B44)+SUMIFS(Покупки!$S$7:$S$18,Покупки!$P$7:$P$18,$C$32,Покупки!$G$7:$G$18,">="&$X44,Покупки!$G$7:$G$18,"<="&$B44))) | F44: =IF($C$32="",0,SUMIFS(Операции!$Q$10:$Q$1009,Операции!$D$10:$D$1009,"Доход",Операции!$H$10:$H$1009,$C$32,Операции!$C$10:$C$1009,">="&$X44,Операции!$C$10:$C$1009,"<="&$B44)+SUMIFS(Журнал!$P$10:$P$1509,Журнал!$D$10:$D$1509,"Доход",Журнал!$J$10:$J$1509,$C$32,Журнал!$C$10:$C$1509,">="&$X44,Журнал!$C$10:$C$1509,"<="&$B44)+SUMIFS(Постоянные!$AC$8:$AC$367,Постоянные!$Z$8:$Z$367,"Доход",Постоянные!$AE$8:$AE$367,$C$32,Постоянные!$Y$8:$Y$367,">="&$X44,Постоянные!$Y$8:$Y$367,"<="&$B44)+SUMIFS(Операции!$Q$10:$Q$1009,Операции!$D$10:$D$1009,"Перевод",Операции!$I$10:$I$1009,$C$32,Операции!$C$10:$C$1009,">="&$X44,Операции!$C$10:$C$1009,"<="&$B44)-SUMIFS(Операции!$Q$10:$Q$1009,Операции!$D$10:$D$1009,"Перевод",Операции!$H$10:$H$1009,$C$32,Операции!$C$10:$C$1009,">="&$X44,Операции!$C$10:$C$1009,"<="&$B44)) | G44: =C44+D44+E44+F44 | H44: =DATE(YEAR(B44),MONTH(B44),MAX(1,MIN(28,N($C$36)))) | I44: =IF($C$33="Да",-MIN(0,G44),0) | X44: =B43+1 | Y44: =IF(AND(H44<=$Y$4,H44>=$C$4),I44,0)
